Workbook

Sheet All Services
A1: Sanaku — every service in the catalog
A2: Blue figures are the catalog prices — edit these and every other tab follows. Generated from docs/catalog.json; re-pull it after changing a price in Supabase.
A4: Code | B4: Service | C4: Type | D4: Verticals | E4: Setup | F4: Monthly | G4: Included | H4: Unit | I4: Overage | J4: Per qualified lead | K4: BAA required | L4: Status
A5: bundle_complete_home | B5: The Whole System | C5: bundle | D5: home_services | E5: 2500 | F5: 1250 | G5: 700 | H5: minutes | I5: 0.45 | J5: 15 | L5: In development
A6: bundle_complete_law | B6: The Whole System | C6: bundle | D6: law_firm | E6: 4450 | F6: 2150 | G6: 700 | H6: minutes | I6: 0.55 | J6: 35 | L6: In development
A7: bundle_complete_medical | B7: The Whole System | C7: bundle | D7: medical | E7: 2800 | F7: 1400 | G7: 400 | H7: minutes | I7: 0.55 | K7: Yes | L7: In development
A8: bundle_voice_home | B8: Complete Phone Cover | C8: bundle | D8: home_services | E8: 1100 | F8: 550 | G8: 700 | H8: minutes | I8: 0.45 | J8: 20 | L8: In development
A9: bundle_voice_law | B9: Complete Phone Cover | C9: bundle | D9: law_firm | E9: 2000 | F9: 900 | G9: 700 | H9: minutes | I9: 0.55 | J9: 35 | L9: In development
A10: bundle_recovery_home | B10: Complete Lead Recovery | C10: bundle | D10: home_services | E10: 1200 | F10: 650 | G10: 500 | H10: texts | I10: 0.05 | J10: 15 | L10: In development
A11: bundle_recovery_law | B11: Complete Lead Recovery | C11: bundle | D11: law_firm | E11: 2200 | F11: 1100 | G11: 500 | H11: texts | I11: 0.07 | J11: 35 | L11: In development
A12: bundle_recovery_medical | B12: Complete Lead Recovery | C12: bundle | D12: medical | E12: 1600 | F12: 850 | G12: 500 | H12: texts | I12: 0.07 | K12: Yes | L12: In development
A13: voice_reception_home | B13: AI Phone Agent | C13: voice | D13: home_services | E13: 750 | F13: 350 | G13: 400 | H13: min | I13: 0.45 | L13: Available now
A14: voice_reception_law | B14: AI Intake Agent | C14: voice | D14: law_firm | E14: 1500 | F14: 650 | G14: 400 | H14: min | I14: 0.55 | J14: 35 | L14: In development
A15: voice_reception_medical | B15: AI Front-Desk Agent | C15: voice | D15: medical | E15: 1500 | F15: 650 | G15: 400 | H15: min | I15: 0.55 | K15: Yes | L15: In development
A16: voice_callback_home | B16: Instant Lead Callback | C16: voice | D16: home_services | E16: 500 | F16: 250 | G16: 300 | H16: min | I16: 0.45 | J16: 20 | L16: In development
A17: voice_callback_law | B17: Instant Lead Callback | C17: voice | D17: law_firm | E17: 1000 | F17: 450 | G17: 300 | H17: min | I17: 0.55 | J17: 35 | L17: In development
A18: voice_afterhours | B18: After-Hours Answering | C18: voice | D18: home_services, law_firm, medical | E18: 350 | F18: 175 | G18: 150 | H18: min | I18: 0.45 | L18: In development
A19: voice_spanish | B19: Spanish-Speaking Agent | C19: voice | D19: home_services, law_firm, medical | E19: 250 | F19: 100 | H19: min | L19: In development
A20: sms_reviews | B20: Review Requests | C20: messaging | D20: home_services, law_firm | E20: 250 | F20: 100 | H20: min | L20: In development
A21: recover_missed_call_home | B21: Missed-Call Text-Back | C21: messaging | D21: home_services | E21: 500 | F21: 250 | G21: 500 | H21: texts | I21: 0.05 | J21: 15 | L21: Available now
A22: recover_missed_call_law | B22: Missed-Call Text-Back | C22: messaging | D22: law_firm | E22: 900 | F22: 450 | G22: 500 | H22: texts | I22: 0.07 | J22: 35 | L22: Available now
A23: recover_missed_call_medical | B23: Missed-Call Text-Back | C23: messaging | D23: medical | E23: 650 | F23: 325 | G23: 500 | H23: texts | I23: 0.07 | K23: Yes | L23: Available now
A24: after_hours_intake_home | B24: After-Hours Intake | C24: messaging | D24: home_services | E24: 400 | F24: 200 | H24: texts | J24: 15 | L24: Available now
A25: after_hours_intake_law | B25: After-Hours Intake | C25: messaging | D25: law_firm | E25: 750 | F25: 350 | H25: texts | J25: 35 | L25: Available now
A26: after_hours_intake_medical | B26: After-Hours Intake | C26: messaging | D26: medical | E26: 550 | F26: 275 | H26: texts | K26: Yes | L26: Available now
A27: nurture_home | B27: Lead Nurture Sequences | C27: messaging | D27: home_services | E27: 500 | F27: 225 | H27: texts | J27: 15 | L27: In development
A28: nurture_law | B28: Lead Nurture Sequences | C28: messaging | D28: law_firm | E28: 900 | F28: 400 | H28: texts | J28: 35 | L28: In development
A29: nurture_medical | B29: Recall & Reactivation | C29: messaging | D29: medical | E29: 500 | F29: 250 | H29: texts | K29: Yes | L29: In development
A30: reminders_home | B30: Reminders & No-Show Recovery | C30: messaging | D30: home_services | E30: 350 | F30: 175 | H30: texts | L30: In development
A31: reminders_law | B31: Reminders & No-Show Recovery | C31: messaging | D31: law_firm | E31: 600 | F31: 300 | H31: texts | L31: In development
A32: reminders_medical | B32: Reminders & No-Show Recovery | C32: messaging | D32: medical | E32: 450 | F32: 225 | H32: texts | K32: Yes | L32: In development
A34: Healthcare rows carry no per-lead fee by design — per-patient compensation can implicate anti-kickback and fee-splitting rules. The database constraint sanaku_addons_pricing_legal rejects one, so it cannot be entered by mistake.

Sheet Packages & Savings
A1: What each package contains, and what it saves
A2: Every number on this tab is a formula reading All Services. Change a member's price there and the package saving here recalculates.
A4: Package / part | B4: Code | C4: Setup | D4: Monthly | E4: Note
A5: The Whole System — home_services | B5: bundle_complete_home | C5: ='All Services'!E5 | D5: ='All Services'!F5 | E5: In development
A6: AI Phone Agent | B6: voice_reception_home | C6: ='All Services'!E13 | D6: ='All Services'!F13
A7: Instant Lead Callback | B7: voice_callback_home | C7: ='All Services'!E16 | D7: ='All Services'!F16
A8: Spanish-Speaking Agent | B8: voice_spanish | C8: ='All Services'!E19 | D8: ='All Services'!F19
A9: Review Requests | B9: sms_reviews | C9: ='All Services'!E20 | D9: ='All Services'!F20
A10: Missed-Call Text-Back | B10: recover_missed_call_home | C10: ='All Services'!E21 | D10: ='All Services'!F21
A11: After-Hours Intake | B11: after_hours_intake_home | C11: ='All Services'!E24 | D11: ='All Services'!F24
A12: Lead Nurture Sequences | B12: nurture_home | C12: ='All Services'!E27 | D12: ='All Services'!F27
A13: Reminders & No-Show Recovery | B13: reminders_home | C13: ='All Services'!E30 | D13: ='All Services'!F30
A14: Bought separately | C14: =SUM(C6:C13) | D14: =SUM(D6:D13)
A15: You save | C15: =C14-C5 | D15: =D14-D5 | E15: =IF(C14=0,0,(C14-C5)/C14) | F15: =IF(D14=0,0,(D14-D5)/D14)
A17: The Whole System — law_firm | B17: bundle_complete_law | C17: ='All Services'!E6 | D17: ='All Services'!F6 | E17: In development
A18: AI Intake Agent | B18: voice_reception_law | C18: ='All Services'!E14 | D18: ='All Services'!F14
A19: Instant Lead Callback | B19: voice_callback_law | C19: ='All Services'!E17 | D19: ='All Services'!F17
A20: Spanish-Speaking Agent | B20: voice_spanish | C20: ='All Services'!E19 | D20: ='All Services'!F19
A21: Review Requests | B21: sms_reviews | C21: ='All Services'!E20 | D21: ='All Services'!F20
A22: Missed-Call Text-Back | B22: recover_missed_call_law | C22: ='All Services'!E22 | D22: ='All Services'!F22
A23: After-Hours Intake | B23: after_hours_intake_law | C23: ='All Services'!E25 | D23: ='All Services'!F25
A24: Lead Nurture Sequences | B24: nurture_law | C24: ='All Services'!E28 | D24: ='All Services'!F28
A25: Reminders & No-Show Recovery | B25: reminders_law | C25: ='All Services'!E31 | D25: ='All Services'!F31
A26: Bought separately | C26: =SUM(C18:C25) | D26: =SUM(D18:D25)
A27: You save | C27: =C26-C17 | D27: =D26-D17 | E27: =IF(C26=0,0,(C26-C17)/C26) | F27: =IF(D26=0,0,(D26-D17)/D26)
A29: The Whole System — medical | B29: bundle_complete_medical | C29: ='All Services'!E7 | D29: ='All Services'!F7 | E29: In development
A30: AI Front-Desk Agent | B30: voice_reception_medical | C30: ='All Services'!E15 | D30: ='All Services'!F15
A31: Spanish-Speaking Agent | B31: voice_spanish | C31: ='All Services'!E19 | D31: ='All Services'!F19
A32: Missed-Call Text-Back | B32: recover_missed_call_medical | C32: ='All Services'!E23 | D32: ='All Services'!F23
A33: After-Hours Intake | B33: after_hours_intake_medical | C33: ='All Services'!E26 | D33: ='All Services'!F26
A34: Recall & Reactivation | B34: nurture_medical | C34: ='All Services'!E29 | D34: ='All Services'!F29
A35: Reminders & No-Show Recovery | B35: reminders_medical | C35: ='All Services'!E32 | D35: ='All Services'!F32
A36: Bought separately | C36: =SUM(C30:C35) | D36: =SUM(D30:D35)
A37: You save | C37: =C36-C29 | D37: =D36-D29 | E37: =IF(C36=0,0,(C36-C29)/C36) | F37: =IF(D36=0,0,(D36-D29)/D36)
A39: Complete Phone Cover — home_services | B39: bundle_voice_home | C39: ='All Services'!E8 | D39: ='All Services'!F8 | E39: In development
A40: AI Phone Agent | B40: voice_reception_home | C40: ='All Services'!E13 | D40: ='All Services'!F13
A41: Instant Lead Callback | B41: voice_callback_home | C41: ='All Services'!E16 | D41: ='All Services'!F16
A42: Spanish-Speaking Agent | B42: voice_spanish | C42: ='All Services'!E19 | D42: ='All Services'!F19
A43: Bought separately | C43: =SUM(C40:C42) | D43: =SUM(D40:D42)
A44: You save | C44: =C43-C39 | D44: =D43-D39 | E44: =IF(C43=0,0,(C43-C39)/C43) | F44: =IF(D43=0,0,(D43-D39)/D43)
...

Sheet Home Services
A1: Home Services — what this vertical can buy
A3: Service | B3: Code | C3: Type | D3: Setup | E3: Monthly | F3: Per lead | G3: Status
A4: The Whole System | B4: bundle_complete_home | C4: bundle | D4: ='All Services'!E5 | E4: ='All Services'!F5 | F4: ='All Services'!J5 | G4: In development
A5: Complete Phone Cover | B5: bundle_voice_home | C5: bundle | D5: ='All Services'!E8 | E5: ='All Services'!F8 | F5: ='All Services'!J8 | G5: In development
A6: Complete Lead Recovery | B6: bundle_recovery_home | C6: bundle | D6: ='All Services'!E10 | E6: ='All Services'!F10 | F6: ='All Services'!J10 | G6: In development
A7: AI Phone Agent | B7: voice_reception_home | C7: voice | D7: ='All Services'!E13 | E7: ='All Services'!F13 | F7: ='All Services'!J13 | G7: Available now
A8: Instant Lead Callback | B8: voice_callback_home | C8: voice | D8: ='All Services'!E16 | E8: ='All Services'!F16 | F8: ='All Services'!J16 | G8: In development
A9: After-Hours Answering | B9: voice_afterhours | C9: voice | D9: ='All Services'!E18 | E9: ='All Services'!F18 | F9: ='All Services'!J18 | G9: In development
A10: Spanish-Speaking Agent | B10: voice_spanish | C10: voice | D10: ='All Services'!E19 | E10: ='All Services'!F19 | F10: ='All Services'!J19 | G10: In development
A11: Review Requests | B11: sms_reviews | C11: messaging | D11: ='All Services'!E20 | E11: ='All Services'!F20 | F11: ='All Services'!J20 | G11: In development
A12: Missed-Call Text-Back | B12: recover_missed_call_home | C12: messaging | D12: ='All Services'!E21 | E12: ='All Services'!F21 | F12: ='All Services'!J21 | G12: Available now
A13: After-Hours Intake | B13: after_hours_intake_home | C13: messaging | D13: ='All Services'!E24 | E13: ='All Services'!F24 | F13: ='All Services'!J24 | G13: Available now
A14: Lead Nurture Sequences | B14: nurture_home | C14: messaging | D14: ='All Services'!E27 | E14: ='All Services'!F27 | F14: ='All Services'!J27 | G14: In development
A15: Reminders & No-Show Recovery | B15: reminders_home | C15: messaging | D15: ='All Services'!E30 | E15: ='All Services'!F30 | F15: ='All Services'!J30 | G15: In development

Sheet Law Firms
A1: Law Firms — what this vertical can buy
A3: Service | B3: Code | C3: Type | D3: Setup | E3: Monthly | F3: Per lead | G3: Status
A4: The Whole System | B4: bundle_complete_law | C4: bundle | D4: ='All Services'!E6 | E4: ='All Services'!F6 | F4: ='All Services'!J6 | G4: In development
A5: Complete Phone Cover | B5: bundle_voice_law | C5: bundle | D5: ='All Services'!E9 | E5: ='All Services'!F9 | F5: ='All Services'!J9 | G5: In development
A6: Complete Lead Recovery | B6: bundle_recovery_law | C6: bundle | D6: ='All Services'!E11 | E6: ='All Services'!F11 | F6: ='All Services'!J11 | G6: In development
A7: AI Intake Agent | B7: voice_reception_law | C7: voice | D7: ='All Services'!E14 | E7: ='All Services'!F14 | F7: ='All Services'!J14 | G7: In development
A8: Instant Lead Callback | B8: voice_callback_law | C8: voice | D8: ='All Services'!E17 | E8: ='All Services'!F17 | F8: ='All Services'!J17 | G8: In development
A9: After-Hours Answering | B9: voice_afterhours | C9: voice | D9: ='All Services'!E18 | E9: ='All Services'!F18 | F9: ='All Services'!J18 | G9: In development
A10: Spanish-Speaking Agent | B10: voice_spanish | C10: voice | D10: ='All Services'!E19 | E10: ='All Services'!F19 | F10: ='All Services'!J19 | G10: In development
A11: Review Requests | B11: sms_reviews | C11: messaging | D11: ='All Services'!E20 | E11: ='All Services'!F20 | F11: ='All Services'!J20 | G11: In development
A12: Missed-Call Text-Back | B12: recover_missed_call_law | C12: messaging | D12: ='All Services'!E22 | E12: ='All Services'!F22 | F12: ='All Services'!J22 | G12: Available now
A13: After-Hours Intake | B13: after_hours_intake_law | C13: messaging | D13: ='All Services'!E25 | E13: ='All Services'!F25 | F13: ='All Services'!J25 | G13: Available now
A14: Lead Nurture Sequences | B14: nurture_law | C14: messaging | D14: ='All Services'!E28 | E14: ='All Services'!F28 | F14: ='All Services'!J28 | G14: In development
A15: Reminders & No-Show Recovery | B15: reminders_law | C15: messaging | D15: ='All Services'!E31 | E15: ='All Services'!F31 | F15: ='All Services'!J31 | G15: In development

Sheet Medical
A1: Medical — what this vertical can buy
A3: Service | B3: Code | C3: Type | D3: Setup | E3: Monthly | F3: Per lead | G3: Status
A4: The Whole System | B4: bundle_complete_medical | C4: bundle | D4: ='All Services'!E7 | E4: ='All Services'!F7 | F4: ='All Services'!J7 | G4: In development
A5: Complete Lead Recovery | B5: bundle_recovery_medical | C5: bundle | D5: ='All Services'!E12 | E5: ='All Services'!F12 | F5: ='All Services'!J12 | G5: In development
A6: AI Front-Desk Agent | B6: voice_reception_medical | C6: voice | D6: ='All Services'!E15 | E6: ='All Services'!F15 | F6: ='All Services'!J15 | G6: In development
A7: After-Hours Answering | B7: voice_afterhours | C7: voice | D7: ='All Services'!E18 | E7: ='All Services'!F18 | F7: ='All Services'!J18 | G7: In development
A8: Spanish-Speaking Agent | B8: voice_spanish | C8: voice | D8: ='All Services'!E19 | E8: ='All Services'!F19 | F8: ='All Services'!J19 | G8: In development
A9: Missed-Call Text-Back | B9: recover_missed_call_medical | C9: messaging | D9: ='All Services'!E23 | E9: ='All Services'!F23 | F9: ='All Services'!J23 | G9: Available now
A10: After-Hours Intake | B10: after_hours_intake_medical | C10: messaging | D10: ='All Services'!E26 | E10: ='All Services'!F26 | F10: ='All Services'!J26 | G10: Available now
A11: Recall & Reactivation | B11: nurture_medical | C11: messaging | D11: ='All Services'!E29 | E11: ='All Services'!F29 | F11: ='All Services'!J29 | G11: In development
A12: Reminders & No-Show Recovery | B12: reminders_medical | C12: messaging | D12: ='All Services'!E32 | E12: ='All Services'!F32 | F12: ='All Services'!J32 | G12: In development
A14: Every medical service requires a signed BAA covering every vendor in the path before go-live, and is flat-fee only.

Sheet Scenarios
A1: What one client is worth in year one
A2: Setup plus twelve months. Edit the client count in blue to size a book of business. Revenue only — no cost data exists in the system, so there is no margin here to show.
A4: Package | B4: Clients | C4: Setup each | D4: Monthly each | E4: Year one each | F4: Year one total
A5: The Whole System — home_services | B5: 1 | C5: ='All Services'!E5 | D5: ='All Services'!F5 | E5: =C5+(D5*12) | F5: =B5*E5
A6: The Whole System — law_firm | B6: 1 | C6: ='All Services'!E6 | D6: ='All Services'!F6 | E6: =C6+(D6*12) | F6: =B6*E6
A7: The Whole System — medical | B7: 1 | C7: ='All Services'!E7 | D7: ='All Services'!F7 | E7: =C7+(D7*12) | F7: =B7*E7
A8: Complete Phone Cover — home_services | B8: 1 | C8: ='All Services'!E8 | D8: ='All Services'!F8 | E8: =C8+(D8*12) | F8: =B8*E8
A9: Complete Phone Cover — law_firm | B9: 1 | C9: ='All Services'!E9 | D9: ='All Services'!F9 | E9: =C9+(D9*12) | F9: =B9*E9
A10: Complete Lead Recovery — home_services | B10: 1 | C10: ='All Services'!E10 | D10: ='All Services'!F10 | E10: =C10+(D10*12) | F10: =B10*E10
A11: Complete Lead Recovery — law_firm | B11: 1 | C11: ='All Services'!E11 | D11: ='All Services'!F11 | E11: =C11+(D11*12) | F11: =B11*E11
A12: Complete Lead Recovery — medical | B12: 1 | C12: ='All Services'!E12 | D12: ='All Services'!F12 | E12: =C12+(D12*12) | F12: =B12*E12
A13: Total | F13: =SUM(F5:F12)
A15: Excludes per-lead fees and any usage beyond the included allowance, both of which vary by client. Year one only — setup is not repeated in year two.
